Workbook

Sheet Assumptions
A1: Agent Economics: Cost Model Assumptions
A2: Strategy, Insight & Intelligence — March 2026
A4: 1. API Token Pricing (per 1M tokens, USD)
A5: Sources: Official pricing pages as at March 2026. Prices subject to frequent change.
A7: Provider | B7: Model | C7: Tier | D7: Input $/MTok | E7: Output $/MTok | F7: Context Window | G7: Capability Rating (1–5) | H7: Notes
A8: Anthropic | B8: Claude Opus 4.6 | C8: Frontier | D8: 5 | E8: 25 | F8: 1M | G8: 5 | H8: Top reasoning, extended thinking, agentic
A9: Anthropic | B9: Claude Sonnet 4.6 | C9: Strong mid-tier | D9: 3 | E9: 15 | F9: 1M | G9: 4 | H9: Strong all-rounder, good agentic performance
A10: Anthropic | B10: Claude Haiku 4.5 | C10: Fast/cheap | D10: 1 | E10: 5 | F10: 200K | G10: 3 | H10: High volume, structured tasks
A11: OpenAI | B11: GPT-5.4 | C11: Frontier | D11: 2.5 | E11: 15 | F11: 1M | G11: 5 | H11: Latest flagship, multimodal
A12: OpenAI | B12: o3 | C12: Reasoning | D12: 2 | E12: 8 | F12: 200K | G12: 4 | H12: Complex multi-step reasoning
A13: OpenAI | B13: o4-mini | C13: Fast reasoning | D13: 1.1 | E13: 4.4 | F13: 200K | G13: 3 | H13: Cost-efficient reasoning
A14: OpenAI | B14: GPT-4o | C14: Mid-tier | D14: 2.5 | E14: 10 | F14: 128K | G14: 4 | H14: Multimodal workhorse
A15: Google | B15: Gemini 3.1 Pro | C15: Frontier | D15: 2 | E15: 12 | F15: 1M | G15: 5 | H15: Latest frontier, strong coding/reasoning
A16: Google | B16: Gemini 2.5 Pro | C16: Prior gen frontier | D16: 1.25 | E16: 10 | F16: 1M | G16: 4 | H16: Strong but superseded by 3.1
A17: Google | B17: Gemini 2.5 Flash | C17: Fast/cheap | D17: 0.3 | E17: 2.5 | F17: 1M | G17: 3 | H17: High volume tasks
A18: Google | B18: Gemini 2.5 Flash-Lite | C18: Ultra-cheap | D18: 0.1 | E18: 0.4 | F18: 1M | G18: 2 | H18: Simplest classification only
A19: xAI | B19: Grok 4 | C19: Frontier | D19: 3 | E19: 15 | F19: 256K | G19: 4 | H19: Strong reasoning, web-connected
... A24: Mistral | B24: Codestral | C24: Code specialist | D24: 0.2 | E24: 0.6 | F24: 256K | G24: 3 | H24: Code generation/review specialist
A26: 2. FX Assumptions
A27: GBP/USD Rate | B27: 1.29 | C27: Approximate spot rate, March 2026
A29: 3. UK Financial Services — Fully-Loaded FTE Cost Assumptions
A30: Based on public benchmarks: Robert Half, Glassdoor, major UK bank annual report indicators.
A32: Role / Grade | B32: Base Salary (£) | C32: Fully-Loaded Multiplier | D32: Fully-Loaded Cost (£) | E32: Cost/Hour (£) | F32: Cost/Min (£) | G32: Notes
A33: Junior Analyst / Operations (Grade 5-6) | B33: 32000 | C33: 1.85 | D33: =B33*C33 -> 59200 | E33: =D33/1820 -> 32.527473 | F33: =E33/60 -> 0.54212454 | G33: NI, pension, office, IT, management, training, attrition
A34: Senior Analyst / Team Lead (Grade 7-8) | B34: 48000 | C34: 1.85 | D34: =B34*C34 -> 88800 | E34: =D34/1820 -> 48.791209 | F34: =E34/60 -> 0.81318681 | G34: Includes regulatory training costs
A35: Compliance Officer | B35: 55000 | C35: 1.9 | D35: =B35*C35 -> 104500 | E35: =D35/1820 -> 57.417582 | F35: =E35/60 -> 0.95695971 | G35: Higher training and certification overhead
A36: Operations Manager | B36: 62000 | C36: 1.85 | D36: =B36*C36 -> 114700 | E36: =D36/1820 -> 63.021978 | F36: =E36/60 -> 1.0503663 | G36: Management overhead allocation
A37: Senior Manager / VP equivalent | B37: 85000 | C37: 1.9 | D37: =B37*C37 -> 161500 | E37: =D37/1820 -> 88.736264 | F37: =E37/60 -> 1.4789377 | G37: Bonus provision, higher benefits
A38: Director / Head of Function | B38: 120000 | C38: 1.95 | D38: =B38*C38 -> 234000 | E38: =D38/1820 -> 128.57143 | F38: =E38/60 -> 2.1428571 | G38: Significant variable comp provision
A40: Productive hours assumption: 1,820/year (52 weeks x 5 days x 7 hrs)
A41: Fully-loaded multiplier includes: Employer NI (13.8%), pension (5-10%), office/IT costs, HR/management, training, attrition/recruitment
A43: 4. Estimated Token Consumption per Task Type
A44: Conservative estimates based on typical agentic workflows. All values are adjustable inputs.
A46: Task Category | B46: Avg Input Tokens | C46: Avg Output Tokens | D46: Total Tokens | E46: Agent Calls per Task | F46: Total Tokens per Task
A47: Simple classification / triage | B47: 2000 | C47: 500 | D47: =B47+C47 -> 2500 | E47: 1 | F47: =D47*E47 -> 2500
A48: Document review (per page) | B48: 4000 | C48: 1500 | D48: =B48+C48 -> 5500 | E48: 1 | F48: =D48*E48 -> 5500
A49: KYC data extraction and check | B49: 8000 | C49: 3000 | D49: =B49+C49 -> 11000 | E49: 3 | F49: =D49*E49 -> 33000
A50: Complaint analysis and draft response | B50: 6000 | C50: 2500 | D50: =B50+C50 -> 8500 | E50: 2 | F50: =D50*E50 -> 17000
A51: Fraud alert triage | B51: 3000 | C51: 1000 | D51: =B51+C51 -> 4000 | E51: 2 | F51: =D51*E51 -> 8000
A52: MI report generation (per section) | B52: 5000 | C52: 3000 | D52: =B52+C52 -> 8000 | E52: 4 | F52: =D52*E52 -> 32000
...

Sheet Capability Assessment
A1: Model Capability Assessment by Process Type
A2: Rating: 1 = unsuitable, 2 = basic/partial, 3 = adequate, 4 = strong, 5 = excellent. All ratings are editable assumptions.
A3: This sheet assesses which models can realistically automate each process end-to-end vs partially.
A5: Process | B5: Opus 4.6 | C5: Sonnet 4.6 | D5: Haiku 4.5 | E5: GPT-5.4 | F5: o3 | G5: o4-mini | H5: Gemini 3.1 Pro | I5: Gemini 2.5 Flash | J5: Grok 4 | K5: DeepSeek V4 | L5: DeepSeek R2 | M5: Mistral Large 3
A6: KYC / Onboarding Check | B6: 5 | C6: 4 | D6: 3 | E6: 5 | F6: 4 | G6: 3 | H6: 5 | I6: 2 | J6: 4 | K6: 4 | L6: 4 | M6: 3
A7: Fraud Alert Triage | B7: 5 | C7: 4 | D7: 3 | E7: 5 | F7: 5 | G7: 4 | H7: 4 | I7: 3 | J7: 4 | K7: 4 | L7: 4 | M7: 3
A8: Mortgage Application Review | B8: 5 | C8: 4 | D8: 2 | E8: 5 | F8: 4 | G8: 2 | H8: 5 | I8: 1 | J8: 4 | K8: 3 | L8: 4 | M8: 2
A9: Customer Complaint Resolution | B9: 5 | C9: 5 | D9: 3 | E9: 5 | F9: 3 | G9: 2 | H9: 4 | I9: 2 | J9: 4 | K9: 3 | L9: 3 | M9: 3
A10: Regulatory Document Review | B10: 5 | C10: 4 | D10: 2 | E10: 5 | F10: 5 | G10: 2 | H10: 5 | I10: 1 | J10: 4 | K10: 3 | L10: 5 | M10: 2
A11: MI / Management Reporting | B11: 4 | C11: 4 | D11: 3 | E11: 4 | F11: 4 | G11: 3 | H11: 4 | I11: 3 | J11: 3 | K11: 4 | L11: 3 | M11: 3
A13: Rating key:
A14: 5 = Excellent: can automate end-to-end with minimal oversight
A15: 4 = Strong: can automate end-to-end but benefits from human review
A16: 3 = Adequate: can handle with oversight, may struggle with edge cases
A17: 2 = Partial: can assist but cannot drive the process autonomously
A18: 1 = Unsuitable: insufficient capability for this task type
A20: Minimum Capability for Deployment
A21: These thresholds determine which models appear in the cost comparison. Editable.
A22: Deployment Mode | B22: Minimum Rating Required | C22: Notes
A23: AI Solo (autonomous) | B23: 4 | C23: Model must be rated 4+ to be considered for autonomous deployment
A24: Hybrid (human in the loop) | B24: 3 | C24: Model must be rated 3+ to be considered for human-in-the-loop deployment

Sheet Automatability
A1: Process Automatability Assumptions
A2: What proportion of each process can realistically be automated? These are adjustable assumptions.
A3: Yellow cells are editable inputs. Update these in collaboration with the business to reflect actual process knowledge.
A5: Business Process | B5: Total Human Time (mins) | C5: % Automatable (AI Solo) | D5: % Automatable (Hybrid) | E5: Residual Human Time: AI Solo (mins) | F5: Residual Human Time: Hybrid (mins) | G5: AI Solo: Automated Portion (mins) | H5: Hybrid: Automated Portion (mins) | I5: Rationale / Working
A6: KYC / Onboarding Check | B6: 45 | C6: 0.85 | D6: 0.75 | E6: =B6*(1-C6) -> 6.75 | F6: =B6*(1-D6) -> 11.25 | G6: =B6*C6 -> 38.25 | H6: =B6*D6 -> 33.75 | I6: Data extraction and matching highly automatable. Final sign-off, complex cases, PEP checks require human judgement.
A7: Fraud Alert Triage | B7: 8 | C7: 0.9 | D7: 0.8 | E7: =B7*(1-C7) -> 0.8 | F7: =B7*(1-D7) -> 1.6 | G7: =B7*C7 -> 7.2 | H7: =B7*D7 -> 6.4 | I7: Pattern matching and initial scoring very strong for AI. Edge cases and escalation decisions need human review.
A8: Mortgage Application Review | B8: 60 | C8: 0.7 | D8: 0.65 | E8: =B8*(1-C8) -> 18 | F8: =B8*(1-D8) -> 21 | G8: =B8*C8 -> 42 | H8: =B8*D8 -> 39 | I8: Document parsing and data extraction strong. Affordability judgement, complex income structures, exceptions need humans.
A9: Customer Complaint Resolution | B9: 35 | C9: 0.65 | D9: 0.6 | E9: =B9*(1-C9) -> 12.25 | F9: =B9*(1-D9) -> 14 | G9: =B9*C9 -> 22.75 | H9: =B9*D9 -> 21 | I9: Drafting, categorisation, root cause analysis automatable. Tone, empathy in complex cases, regulatory judgement less so.
A10: Regulatory Document Review | B10: 90 | C10: 0.75 | D10: 0.7 | E10: =B10*(1-C10) -> 22.5 | F10: =B10*(1-D10) -> 27 | G10: =B10*C10 -> 67.5 | H10: =B10*D10 -> 63 | I10: Clause extraction, comparison, flagging strong. Novel interpretations, ambiguous requirements need expert judgement.
A11: MI / Management Reporting | B11: 120 | C11: 0.9 | D11: 0.85 | E11: =B11*(1-C11) -> 12 | F11: =B11*(1-D11) -> 18 | G11: =B11*C11 -> 108 | H11: =B11*D11 -> 102 | I11: Data aggregation, formatting, narrative generation highly automatable. Strategic interpretation, context less so.

Sheet Process Comparison
A1: Process Cost Comparison: Human vs AI Agent vs Hybrid
A2: Uses automatability assumptions from the Automatability sheet. Costs reflect only the automatable portion.
A4: Reference Model: | B4: Claude Sonnet 4.6
A5: Input cost ($/MTok): | B5: 3
A6: Output cost ($/MTok): | B6: 15
A7: GBP/USD: | B7: =Assumptions!B27 -> 1.29
A9: Business Process | B9: Human Role | C9: Total Human Time (mins) | D9: Full Human Cost/Task (£) | E9: % Automatable (AI Solo) | F9: % Automatable (Hybrid) | G9: Input Tokens | H9: Output Tokens | I9: Agent Calls | J9: AI Token Cost (£) | K9: AI Solo Total (£) | L9: Hybrid Total (£) | M9: Saving: AI Solo vs Human | N9: Saving: Hybrid vs Human
A10: KYC / Onboarding Check | B10: Senior Analyst | C10: =Automatability!B6 -> 45 | D10: =C10*Assumptions!F34 -> 36.593407 | E10: =Automatability!C6 -> 0.85 | F10: =Automatability!D6 -> 0.75 | G10: 8000 | H10: 3000 | I10: 3 | J10: =((G10*$B$5+H10*$B$6)/1000000)*I10/$B$7 -> 0.16046512 | K10: =J10+(C10*(1-E10)*Assumptions!F34) -> 5.6494761 | L10: =J10+(C10*(1-F10)*Assumptions!F34) -> 9.3088168 | M10: =1-(K10/D10) -> 0.84561492 | N10: =1-(L10/D10) -> 0.74561492
A11: Fraud Alert Triage | B11: Junior Analyst | C11: =Automatability!B7 -> 8 | D11: =C11*Assumptions!F33 -> 4.3369963 | E11: =Automatability!C7 -> 0.9 | F11: =Automatability!D7 -> 0.8 | G11: 3000 | H11: 1000 | I11: 2 | J11: =((G11*$B$5+H11*$B$6)/1000000)*I11/$B$7 -> 0.037209302 | K11: =J11+(C11*(1-E11)*Assumptions!F33) -> 0.47090894 | L11: =J11+(C11*(1-F11)*Assumptions!F33) -> 0.90460857 | M11: =1-(K11/D11) -> 0.89142049 | N11: =1-(L11/D11) -> 0.79142049
A12: Mortgage Application Review | B12: Operations Manager | C12: =Automatability!B8 -> 60 | D12: =C12*Assumptions!F36 -> 63.021978 | E12: =Automatability!C8 -> 0.7 | F12: =Automatability!D8 -> 0.65 | G12: 10000 | H12: 4000 | I12: 5 | J12: =((G12*$B$5+H12*$B$6)/1000000)*I12/$B$7 -> 0.34883721 | K12: =J12+(C12*(1-E12)*Assumptions!F36) -> 19.255431 | L12: =J12+(C12*(1-F12)*Assumptions!F36) -> 22.40653 | M12: =1-(K12/D12) -> 0.69446483 | N12: =1-(L12/D12) -> 0.64446483
A13: Customer Complaint Resolution | B13: Senior Analyst | C13: =Automatability!B9 -> 35 | D13: =C13*Assumptions!F34 -> 28.461538 | E13: =Automatability!C9 -> 0.65 | F13: =Automatability!D9 -> 0.6 | G13: 6000 | H13: 2500 | I13: 2 | J13: =((G13*$B$5+H13*$B$6)/1000000)*I13/$B$7 -> 0.086046512 | K13: =J13+(C13*(1-E13)*Assumptions!F34) -> 10.047585 | L13: =J13+(C13*(1-F13)*Assumptions!F34) -> 11.470662 | M13: =1-(K13/D13) -> 0.64697674 | N13: =1-(L13/D13) -> 0.59697674
A14: Regulatory Document Review | B14: Compliance Officer | C14: =Automatability!B10 -> 90 | D14: =C14*Assumptions!F35 -> 86.126374 | E14: =Automatability!C10 -> 0.75 | F14: =Automatability!D10 -> 0.7 | G14: 15000 | H14: 5000 | I14: 3 | J14: =((G14*$B$5+H14*$B$6)/1000000)*I14/$B$7 -> 0.27906977 | K14: =J14+(C14*(1-E14)*Assumptions!F35) -> 21.810663 | L14: =J14+(C14*(1-F14)*Assumptions!F35) -> 26.116982 | M14: =1-(K14/D14) -> 0.74675976 | N14: =1-(L14/D14) -> 0.69675976
A15: MI / Management Reporting | B15: Senior Analyst | C15: =Automatability!B11 -> 120 | D15: =C15*Assumptions!F34 -> 97.582418 | E15: =Automatability!C11 -> 0.9 | F15: =Automatability!D11 -> 0.85 | G15: 5000 | H15: 3000 | I15: 4 | J15: =((G15*$B$5+H15*$B$6)/1000000)*I15/$B$7 -> 0.18604651 | K15: =J15+(C15*(1-E15)*Assumptions!F34) -> 9.9442883 | L15: =J15+(C15*(1-F15)*Assumptions!F34) -> 14.823409 | M15: =1-(K15/D15) -> 0.89809344 | N15: =1-(L15/D15) -> 0.84809344

Sheet Regulatory Stress Case
A1: Regulatory Stress Case: Mandated Human Oversight Scenarios
A2: Models the impact if the FCA or PRA mandates minimum human review rates for AI driven decisions.
A3: Yellow cells are editable. Adjust mandated review rates per process to model different regulatory outcomes.
A5: GBP/USD: | B5: =Assumptions!B27 -> 1.29
A7: Business Process | B7: Base Hybrid Saving (%) | C7: Mandated Review Rate | D7: Review Time per Task (mins) | E7: Reviewer Role Cost/Min | F7: Mandated Review Cost/Task (£) | G7: Stress Case Total/Task (£) | H7: Stress Saving vs Human | I7: Saving Lost vs Base Hybrid
A8: KYC / Onboarding Check | B8: ='Process Comparison'!N10 -> 0.74561492 | C8: 1 | D8: 8 | E8: =Assumptions!F34 -> 0.81318681 | F8: =C8*D8*E8 -> 6.5054945 | G8: ='Process Comparison'!J10+'Process Comparison'!C10*(1-'Process Comparison'!F10)*E8+F8 -> 15.814311 | H8: =1-(G8/'Process Comparison'!D10) -> 0.56783714 | I8: ='Process Comparison'!N10-H8 -> 0.17777778
A9: Fraud Alert Triage | B9: ='Process Comparison'!N11 -> 0.79142049 | C9: 0.5 | D9: 3 | E9: =Assumptions!F33 -> 0.54212454 | F9: =C9*D9*E9 -> 0.81318681 | G9: ='Process Comparison'!J11+'Process Comparison'!C11*(1-'Process Comparison'!F11)*E9+F9 -> 1.7177954 | H9: =1-(G9/'Process Comparison'!D11) -> 0.60392049 | I9: ='Process Comparison'!N11-H9 -> 0.1875
A10: Mortgage Application Review | B10: ='Process Comparison'!N12 -> 0.64446483 | C10: 1 | D10: 12 | E10: =Assumptions!F36 -> 1.0503663 | F10: =C10*D10*E10 -> 12.604396 | G10: ='Process Comparison'!J12+'Process Comparison'!C12*(1-'Process Comparison'!F12)*E10+F10 -> 35.010925 | H10: =1-(G10/'Process Comparison'!D12) -> 0.44446483 | I10: ='Process Comparison'!N12-H10 -> 0.2
A11: Customer Complaint Resolution | B11: ='Process Comparison'!N13 -> 0.59697674 | C11: 0.3 | D11: 8 | E11: =Assumptions!F34 -> 0.81318681 | F11: =C11*D11*E11 -> 1.9516484 | G11: ='Process Comparison'!J13+'Process Comparison'!C13*(1-'Process Comparison'!F13)*E11+F11 -> 13.42231 | H11: =1-(G11/'Process Comparison'!D13) -> 0.52840532 | I11: ='Process Comparison'!N13-H11 -> 0.068571429
A12: Regulatory Document Review | B12: ='Process Comparison'!N14 -> 0.69675976 | C12: 1 | D12: 15 | E12: =Assumptions!F35 -> 0.95695971 | F12: =C12*D12*E12 -> 14.354396 | G12: ='Process Comparison'!J14+'Process Comparison'!C14*(1-'Process Comparison'!F14)*E12+F12 -> 40.471377 | H12: =1-(G12/'Process Comparison'!D14) -> 0.5300931 | I12: ='Process Comparison'!N14-H12 -> 0.16666667
A13: MI / Management Reporting | B13: ='Process Comparison'!N15 -> 0.84809344 | C13: 0.1 | D13: 5 | E13: =Assumptions!F34 -> 0.81318681 | F13: =C13*D13*E13 -> 0.40659341 | G13: ='Process Comparison'!J15+'Process Comparison'!C15*(1-'Process Comparison'!F15)*E13+F13 -> 15.230003 | H13: =1-(G13/'Process Comparison'!D15) -> 0.84392678 | I13: ='Process Comparison'!N15-H13 -> 0.0041666667
A15: Notes on mandated review rates:
A16: 100% = every AI decision reviewed by a qualified human (KYC, mortgage, regulatory docs under Consumer Duty)
A17: 50% = sample based review (fraud triage where false positive tolerance is higher)
A18: 30% = light touch sampling (complaints where human already drafts final response)
A19: 10% = audit only (MI reporting where output is internal and low risk)

Sheet Automatability Sensitivity
A1: Automatability Sensitivity: The Critical Variable
A2: Impact on annual hybrid savings if automatability assumptions are higher or lower than base case.
A3: This is where the real analytical risk lies, not in token pricing.
A5: Business Process | B5: Base Auto. % | C5: Annual Volume | D5: -20pp | E5: -15pp | F5: -10pp | G5: -5pp | H5: Base Case | I5: +5pp | J5: +10pp
A6: KYC / Onboarding Check | B6: =Automatability!D6 -> 0.75 | C6: 50000 | D6: =C6*(Automatability!B6*(Automatability!D6+-0.2)*Assumptions!F34-'Process Comparison'!J10) -> 998295.43 | E6: =C6*(Automatability!B6*(Automatability!D6+-0.15)*Assumptions!F34-'Process Comparison'!J10) -> 1089778.9 | F6: =C6*(Automatability!B6*(Automatability!D6+-0.1)*Assumptions!F34-'Process Comparison'!J10) -> 1181262.5 | G6: =C6*(Automatability!B6*(Automatability!D6+-0.05)*Assumptions!F34-'Process Comparison'!J10) -> 1272746 | H6: =C6*(Automatability!B6*(Automatability!D6)*Assumptions!F34-'Process Comparison'!J10) -> 1364229.5 | I6: =C6*(Automatability!B6*(Automatability!D6+0.05)*Assumptions!F34-'Process Comparison'!J10) -> 1455713 | J6: =C6*(Automatability!B6*(Automatability!D6+0.1)*Assumptions!F34-'Process Comparison'!J10) -> 1547196.5
A7: Fraud Alert Triage | B7: =Automatability!D7 -> 0.8 | C7: 200000 | D7: =C7*(Automatability!B7*(Automatability!D7+-0.2)*Assumptions!F33-'Process Comparison'!J11) -> 512997.7 | E7: =C7*(Automatability!B7*(Automatability!D7+-0.15)*Assumptions!F33-'Process Comparison'!J11) -> 556367.66 | F7: =C7*(Automatability!B7*(Automatability!D7+-0.1)*Assumptions!F33-'Process Comparison'!J11) -> 599737.63 | G7: =C7*(Automatability!B7*(Automatability!D7+-0.05)*Assumptions!F33-'Process Comparison'!J11) -> 643107.59 | H7: =C7*(Automatability!B7*(Automatability!D7)*Assumptions!F33-'Process Comparison'!J11) -> 686477.55 | I7: =C7*(Automatability!B7*(Automatability!D7+0.05)*Assumptions!F33-'Process Comparison'!J11) -> 729847.52 | J7: =C7*(Automatability!B7*(Automatability!D7+0.1)*Assumptions!F33-'Process Comparison'!J11) -> 773217.48
A8: Mortgage Application Review | B8: =Automatability!D8 -> 0.65 | C8: 15000 | D8: =C8*(Automatability!B8*(Automatability!D8+-0.2)*Assumptions!F36-'Process Comparison'!J12) -> 420165.79 | E8: =C8*(Automatability!B8*(Automatability!D8+-0.15)*Assumptions!F36-'Process Comparison'!J12) -> 467432.28 | F8: =C8*(Automatability!B8*(Automatability!D8+-0.1)*Assumptions!F36-'Process Comparison'!J12) -> 514698.76 | G8: =C8*(Automatability!B8*(Automatability!D8+-0.05)*Assumptions!F36-'Process Comparison'!J12) -> 561965.24 | H8: =C8*(Automatability!B8*(Automatability!D8)*Assumptions!F36-'Process Comparison'!J12) -> 609231.73 | I8: =C8*(Automatability!B8*(Automatability!D8+0.05)*Assumptions!F36-'Process Comparison'!J12) -> 656498.21 | J8: =C8*(Automatability!B8*(Automatability!D8+0.1)*Assumptions!F36-'Process Comparison'!J12) -> 703764.69
A9: Customer Complaint Resolution | B9: =Automatability!D9 -> 0.6 | C9: 80000 | D9: =C9*(Automatability!B9*(Automatability!D9+-0.2)*Assumptions!F34-'Process Comparison'!J13) -> 903885.51 | E9: =C9*(Automatability!B9*(Automatability!D9+-0.15)*Assumptions!F34-'Process Comparison'!J13) -> 1017731.7 | F9: =C9*(Automatability!B9*(Automatability!D9+-0.1)*Assumptions!F34-'Process Comparison'!J13) -> 1131577.8 | G9: =C9*(Automatability!B9*(Automatability!D9+-0.05)*Assumptions!F34-'Process Comparison'!J13) -> 1245424 | H9: =C9*(Automatability!B9*(Automatability!D9)*Assumptions!F34-'Process Comparison'!J13) -> 1359270.1 | I9: =C9*(Automatability!B9*(Automatability!D9+0.05)*Assumptions!F34-'Process Comparison'!J13) -> 1473116.3 | J9: =C9*(Automatability!B9*(Automatability!D9+0.1)*Assumptions!F34-'Process Comparison'!J13) -> 1586962.4
A10: Regulatory Document Review | B10: =Automatability!D10 -> 0.7 | C10: 5000 | D10: =C10*(Automatability!B10*(Automatability!D10+-0.2)*Assumptions!F35-'Process Comparison'!J14) -> 213920.59 | E10: =C10*(Automatability!B10*(Automatability!D10+-0.15)*Assumptions!F35-'Process Comparison'!J14) -> 235452.18 | F10: =C10*(Automatability!B10*(Automatability!D10+-0.1)*Assumptions!F35-'Process Comparison'!J14) -> 256983.77 | G10: =C10*(Automatability!B10*(Automatability!D10+-0.05)*Assumptions!F35-'Process Comparison'!J14) -> 278515.37 | H10: =C10*(Automatability!B10*(Automatability!D10)*Assumptions!F35-'Process Comparison'!J14) -> 300046.96 | I10: =C10*(Automatability!B10*(Automatability!D10+0.05)*Assumptions!F35-'Process Comparison'!J14) -> 321578.55 | J10: =C10*(Automatability!B10*(Automatability!D10+0.1)*Assumptions!F35-'Process Comparison'!J14) -> 343110.15
A11: MI / Management Reporting | B11: =Automatability!D11 -> 0.85 | C11: 2000 | D11: =C11*(Automatability!B11*(Automatability!D11+-0.2)*Assumptions!F34-'Process Comparison'!J15) -> 126485.05 | E11: =C11*(Automatability!B11*(Automatability!D11+-0.15)*Assumptions!F34-'Process Comparison'!J15) -> 136243.29 | F11: =C11*(Automatability!B11*(Automatability!D11+-0.1)*Assumptions!F34-'Process Comparison'!J15) -> 146001.53 | G11: =C11*(Automatability!B11*(Automatability!D11+-0.05)*Assumptions!F34-'Process Comparison'!J15) -> 155759.78 | H11: =C11*(Automatability!B11*(Automatability!D11)*Assumptions!F34-'Process Comparison'!J15) -> 165518.02 | I11: =C11*(Automatability!B11*(Automatability!D11+0.05)*Assumptions!F34-'Process Comparison'!J15) -> 175276.26 | J11: =C11*(Automatability!B11*(Automatability!D11+0.1)*Assumptions!F34-'Process Comparison'!J15) -> 185034.5
A12: TOTAL | C12: =SUM(C6:C11) -> 352000 | D12: =SUM(D6:D11) -> 3175750.1 | E12: =SUM(E6:E11) -> 3503006 | F12: =SUM(F6:F11) -> 3830262 | G12: =SUM(G6:G11) -> 4157517.9 | H12: =SUM(H6:H11) -> 4484773.9 | I12: =SUM(I6:I11) -> 4812029.8 | J12: =SUM(J6:J11) -> 5139285.8
A14: Change vs Base Case (£)
D15: -20pp | E15: -15pp | F15: -10pp | G15: -5pp | H15: Base Case | I15: +5pp | J15: +10pp
A16: KYC / Onboarding Check | D16: =D6-H6 -> -365934.07 | E16: =E6-H6 -> -274450.55 | F16: =F6-H6 -> -182967.03 | G16: =G6-H6 -> -91483.516 | H16: =H6-H6 -> 0 | I16: =I6-H6 -> 91483.516 | J16: =J6-H6 -> 182967.03
A17: Fraud Alert Triage | D17: =D7-H7 -> -173479.85 | E17: =E7-H7 -> -130109.89 | F17: =F7-H7 -> -86739.927 | G17: =G7-H7 -> -43369.963 | H17: =H7-H7 -> 0 | I17: =I7-H7 -> 43369.963 | J17: =J7-H7 -> 86739.927
A18: Mortgage Application Review | D18: =D8-H8 -> -189065.93 | E18: =E8-H8 -> -141799.45 | F18: =F8-H8 -> -94532.967 | G18: =G8-H8 -> -47266.484 | H18: =H8-H8 -> 0 | I18: =I8-H8 -> 47266.484 | J18: =J8-H8 -> 94532.967
A19: Customer Complaint Resolution | D19: =D9-H9 -> -455384.62 | E19: =E9-H9 -> -341538.46 | F19: =F9-H9 -> -227692.31 | G19: =G9-H9 -> -113846.15 | H19: =H9-H9 -> 0 | I19: =I9-H9 -> 113846.15 | J19: =J9-H9 -> 227692.31
A20: Regulatory Document Review | D20: =D10-H10 -> -86126.374 | E20: =E10-H10 -> -64594.78 | F20: =F10-H10 -> -43063.187 | G20: =G10-H10 -> -21531.593 | H20: =H10-H10 -> 0 | I20: =I10-H10 -> 21531.593 | J20: =J10-H10 -> 43063.187
A21: MI / Management Reporting | D21: =D11-H11 -> -39032.967 | E21: =E11-H11 -> -29274.725 | F21: =F11-H11 -> -19516.484 | G21: =G11-H11 -> -9758.2418 | H21: =H11-H11 -> 0 | I21: =I11-H11 -> 9758.2418 | J21: =J11-H11 -> 19516.484
A22: TOTAL CHANGE | D22: =SUM(D16:D21) -> -1309023.8 | E22: =SUM(E16:E21) -> -981767.86 | F22: =SUM(F16:F21) -> -654511.9 | G22: =SUM(G16:G21) -> -327255.95 | H22: =SUM(H16:H21) -> 0 | I22: =SUM(I16:I21) -> 327255.95 | J22: =SUM(J16:J21) -> 654511.9

Sheet Error Cost Model
A1: Error Cost Model: Process Specific Error Budgets
A2: What is the cost of AI errors by process? At what error rate does the economic case break?
A3: Yellow cells are editable assumptions. Refine with operational data from pilots.
A5: Business Process | B5: Annual Volume | C5: Estimated AI Error Rate | D5: Errors per Year | E5: Cost per Error: Median (£) | F5: Cost per Error: 95th pctile (£) | G5: Cost per Error: Tail (£) | H5: Annual Error Cost: Median (£) | I5: Annual Error Cost: 95th (£) | J5: Hybrid Annual Saving (£) | K5: Net Saving after Median Errors (£) | L5: Break Even Error Rate
A6: KYC / Onboarding Check | B6: ='Volume Scaling'!B5 -> 50000 | C6: 0.03 | D6: =B6*C6 -> 1500 | E6: 500 | F6: 5000 | G6: 50000 | H6: =D6*E6 -> 750000 | I6: =D6*F6 -> 7500000 | J6: ='Volume Scaling'!H5 -> 1364229.5 | K6: =J6-H6 -> 614229.49 | L6: =IF(B6*E6=0,0,J6/(B6*E6)) -> 0.05456918
A7: Fraud Alert Triage | B7: ='Volume Scaling'!B6 -> 200000 | C7: 0.05 | D7: =B7*C7 -> 10000 | E7: 50 | F7: 500 | G7: 10000 | H7: =D7*E7 -> 500000 | I7: =D7*F7 -> 5000000 | J7: ='Volume Scaling'!H6 -> 686477.55 | K7: =J7-H7 -> 186477.55 | L7: =IF(B7*E7=0,0,J7/(B7*E7)) -> 0.068647755
A8: Mortgage Application Review | B8: ='Volume Scaling'!B7 -> 15000 | C8: 0.02 | D8: =B8*C8 -> 300 | E8: 2000 | F8: 20000 | G8: 200000 | H8: =D8*E8 -> 600000 | I8: =D8*F8 -> 6000000 | J8: ='Volume Scaling'!H7 -> 609231.73 | K8: =J8-H8 -> 9231.7276 | L8: =IF(B8*E8=0,0,J8/(B8*E8)) -> 0.020307724
A9: Customer Complaint Resolution | B9: ='Volume Scaling'!B8 -> 80000 | C9: 0.04 | D9: =B9*C9 -> 3200 | E9: 200 | F9: 2000 | G9: 25000 | H9: =D9*E9 -> 640000 | I9: =D9*F9 -> 6400000 | J9: ='Volume Scaling'!H8 -> 1359270.1 | K9: =J9-H9 -> 719270.13 | L9: =IF(B9*E9=0,0,J9/(B9*E9)) -> 0.084954383
A10: Regulatory Document Review | B10: ='Volume Scaling'!B9 -> 5000 | C10: 0.02 | D10: =B10*C10 -> 100 | E10: 1000 | F10: 15000 | G10: 500000 | H10: =D10*E10 -> 100000 | I10: =D10*F10 -> 1500000 | J10: ='Volume Scaling'!H9 -> 300046.96 | K10: =J10-H10 -> 200046.96 | L10: =IF(B10*E10=0,0,J10/(B10*E10)) -> 0.060009392
A11: MI / Management Reporting | B11: ='Volume Scaling'!B10 -> 2000 | C11: 0.01 | D11: =B11*C11 -> 20 | E11: 100 | F11: 1000 | G11: 5000 | H11: =D11*E11 -> 2000 | I11: =D11*F11 -> 20000 | J11: ='Volume Scaling'!H10 -> 165518.02 | K11: =J11-H11 -> 163518.02 | L11: =IF(B11*E11=0,0,J11/(B11*E11)) -> 0.82759008
A12: TOTAL | B12: =SUM(B6:B11) -> 352000 | D12: =SUM(D6:D11) -> 15120 | H12: =SUM(H6:H11) -> 2592000 | I12: =SUM(I6:I11) -> 26420000 | J12: =SUM(J6:J11) -> 4484773.9 | K12: =SUM(K6:K11) -> 1892773.9
A14: Interpretation:
A15: Break even error rate = the AI error rate at which the annual error cost equals the annual hybrid saving.
A16: If the actual error rate is below this threshold, the economic case remains positive after accounting for errors.
A17: Tail risk (column G) represents worst case scenarios: regulatory fines, FOS referrals, reputational damage.
A18: Error costs should be refined with operational data from pilots. These are working estimates.

Sheet Implementation & Payback
A1: Implementation Costs and Payback Period
A2: Year one investment, ramp up, and steady state economics. Yellow cells are editable.
A4: Phase 1: Year One Investment
A6: Cost Category | B6: Low Estimate (£) | C6: Central Estimate (£) | D6: High Estimate (£) | E6: Notes
A7: Proof of concept and pilot (2 processes) | B7: 150000 | C7: 250000 | D7: 400000 | E7: Agent development, testing, prompt engineering
A8: Orchestration platform build/procurement | B8: 200000 | C8: 350000 | D8: 500000 | E8: Workflow engine, API management, monitoring
A9: QA and audit infrastructure | B9: 100000 | C9: 200000 | D9: 300000 | E9: Logging, explainability tooling, compliance dashboards
A10: Security and data governance | B10: 100000 | C10: 150000 | D10: 250000 | E10: Data classification, access controls, penetration testing
A11: Change management and training | B11: 150000 | C11: 250000 | D11: 400000 | E11: Staff retraining, process redesign, comms
A12: Regulatory engagement and legal | B12: 75000 | C12: 125000 | D12: 200000 | E12: FCA Live Testing, legal review, compliance sign off
A13: Contingency (15%) | B13: =SUM(B7:B12)*0.15 -> 116250 | C13: =SUM(C7:C12)*0.15 -> 198750 | D13: =SUM(D7:D12)*0.15 -> 307500 | E13: Applied to total below
A14: TOTAL YEAR ONE INVESTMENT | B14: =SUM(B7:B13) -> 891250 | C14: =SUM(C7:C13) -> 1523750 | D14: =SUM(D7:D13) -> 2357500
A16: Phase 2: Annual Ongoing Costs (Steady State)
A18: Cost Category | B18: Low (£) | C18: Central (£) | D18: High (£) | E18: Notes
A19: Agent oversight team (2-3 FTEs) | B19: 180000 | C19: 270000 | D19: 360000 | E19: QA, monitoring, escalation handling
A20: Platform maintenance and licences | B20: 75000 | C20: 125000 | D20: 200000 | E20: Orchestration, logging, dashboards
A21: Model API costs (token consumption) | B21: ='Volume Scaling'!F11 -> 2060345.2 | C21: ='Volume Scaling'!F11 -> 2060345.2 | D21: ='Volume Scaling'!F11 -> 2060345.2 | E21: Pulled from Volume Scaling sheet
A22: Prompt engineering and tuning | B22: 50000 | C22: 80000 | D22: 120000 | E22: Ongoing optimisation, new process onboarding
A23: Audit and compliance reporting | B23: 40000 | C23: 60000 | D23: 100000 | E23: Regulatory reporting, internal audit support
A24: TOTAL ANNUAL ONGOING | B24: =SUM(B19:B23) -> 2405345.2 | C24: =SUM(C19:C23) -> 2595345.2 | D24: =SUM(D19:D23) -> 2840345.2
A26: Payback Analysis
A28: Metric | B28: Low | C28: Central | D28: High | E28: Notes
A29: Annual gross hybrid saving | B29: ='Volume Scaling'!H11 -> 4484773.9 | C29: ='Volume Scaling'!H11 -> 4484773.9 | D29: ='Volume Scaling'!H11 -> 4484773.9 | E29: From Volume Scaling sheet
A30: Less: annual ongoing costs | B30: =D24 -> 2840345.2 | C30: =C24 -> 2595345.2 | D30: =B24 -> 2405345.2
A31: Net annual benefit | B31: =B29-B30 -> 1644428.7 | C31: =C29-C30 -> 1889428.7 | D31: =D29-D30 -> 2079428.7
A32: Year one investment | B32: =D14 -> 2357500 | C32: =C14 -> 1523750 | D32: =B14 -> 891250
A33: Simple payback (months) | B33: =IF(B31<=0,"N/A",B32/B31*12) -> 17.203543 | C33: =IF(C31<=0,"N/A",C32/C31*12) -> 9.6775285 | D33: =IF(D31<=0,"N/A",D32/D31*12) -> 5.1432396

Sheet Sensitivity Analysis
A1: Sensitivity Analysis: Token Price Crossover Points
A2: At what token price would the human become cheaper? (Output price as multiple of input price)
A4: Output/Input Price Ratio: | B4: 5
A5: GBP/USD: | B5: =Assumptions!B27 -> 1.29
A7: Crossover Analysis: AI Solo vs Human
A9: Business Process | B9: Human Cost/Task (£) | C9: Total Input Tokens/Task | D9: Total Output Tokens/Task | E9: Crossover Input Price ($/MTok) | F9: Current Price ($/MTok) | G9: Current AI Cost (£) | H9: Headroom (x current price)
A10: ='Process Comparison'!A10 -> KYC / Onboarding Check | B10: ='Process Comparison'!D10 -> 36.593407 | C10: ='Process Comparison'!G10*'Process Comparison'!I10 -> 24000 | D10: ='Process Comparison'!H10*'Process Comparison'!I10 -> 9000 | E10: =B10*$B$5*1000000/(C10+D10*$B$4) -> 684.1376 | F10: ='Process Comparison'!$B$5 -> 3 | G10: ='Process Comparison'!J10 -> 0.16046512 | H10: =E10/F10 -> 228.04587
A11: ='Process Comparison'!A11 -> Fraud Alert Triage | B11: ='Process Comparison'!D11 -> 4.3369963 | C11: ='Process Comparison'!G11*'Process Comparison'!I11 -> 6000 | D11: ='Process Comparison'!H11*'Process Comparison'!I11 -> 2000 | E11: =B11*$B$5*1000000/(C11+D11*$B$4) -> 349.67033 | F11: ='Process Comparison'!$B$5 -> 3 | G11: ='Process Comparison'!J11 -> 0.037209302 | H11: =E11/F11 -> 116.55678
A12: ='Process Comparison'!A12 -> Mortgage Application Review | B12: ='Process Comparison'!D12 -> 63.021978 | C12: ='Process Comparison'!G12*'Process Comparison'!I12 -> 50000 | D12: ='Process Comparison'!H12*'Process Comparison'!I12 -> 20000 | E12: =B12*$B$5*1000000/(C12+D12*$B$4) -> 541.98901 | F12: ='Process Comparison'!$B$5 -> 3 | G12: ='Process Comparison'!J12 -> 0.34883721 | H12: =E12/F12 -> 180.663
A13: ='Process Comparison'!A13 -> Customer Complaint Resolution | B13: ='Process Comparison'!D13 -> 28.461538 | C13: ='Process Comparison'!G13*'Process Comparison'!I13 -> 12000 | D13: ='Process Comparison'!H13*'Process Comparison'!I13 -> 5000 | E13: =B13*$B$5*1000000/(C13+D13*$B$4) -> 992.30769 | F13: ='Process Comparison'!$B$5 -> 3 | G13: ='Process Comparison'!J13 -> 0.086046512 | H13: =E13/F13 -> 330.76923
A14: ='Process Comparison'!A14 -> Regulatory Document Review | B14: ='Process Comparison'!D14 -> 86.126374 | C14: ='Process Comparison'!G14*'Process Comparison'!I14 -> 45000 | D14: ='Process Comparison'!H14*'Process Comparison'!I14 -> 15000 | E14: =B14*$B$5*1000000/(C14+D14*$B$4) -> 925.85852 | F14: ='Process Comparison'!$B$5 -> 3 | G14: ='Process Comparison'!J14 -> 0.27906977 | H14: =E14/F14 -> 308.61951
A15: ='Process Comparison'!A15 -> MI / Management Reporting | B15: ='Process Comparison'!D15 -> 97.582418 | C15: ='Process Comparison'!G15*'Process Comparison'!I15 -> 20000 | D15: ='Process Comparison'!H15*'Process Comparison'!I15 -> 12000 | E15: =B15*$B$5*1000000/(C15+D15*$B$4) -> 1573.5165 | F15: ='Process Comparison'!$B$5 -> 3 | G15: ='Process Comparison'!J15 -> 0.18604651 | H15: =E15/F15 -> 524.50549
A18: Token Price Sensitivity: AI Token Cost per Task (£) at Varying Input Prices
B19: 0.1 | C19: 0.25 | D19: 0.5 | E19: 1 | F19: 2 | G19: 3 | H19: 5 | I19: 10 | J19: 15 | K19: 25 | L19: 50
A20: Input Price ($/MTok) | B20: $0.1 | C20: $0.25 | D20: $0.5 | E20: $1.00 | F20: $2.00 | G20: $3.00 | H20: $5.00 | I20: $10.00 | J20: $15.00 | K20: $25.00 | L20: $50.00 | M20: Human Cost (£)
A21: ='Process Comparison'!A10 -> KYC / Onboarding Check | B21: =(($C$10*B$19+$D$10*B$19*$B$4)/1000000)/$B$5 -> 0.0053488372 | C21: =(($C$10*C$19+$D$10*C$19*$B$4)/1000000)/$B$5 -> 0.013372093 | D21: =(($C$10*D$19+$D$10*D$19*$B$4)/1000000)/$B$5 -> 0.026744186 | E21: =(($C$10*E$19+$D$10*E$19*$B$4)/1000000)/$B$5 -> 0.053488372 | F21: =(($C$10*F$19+$D$10*F$19*$B$4)/1000000)/$B$5 -> 0.10697674 | G21: =(($C$10*G$19+$D$10*G$19*$B$4)/1000000)/$B$5 -> 0.16046512 | H21: =(($C$10*H$19+$D$10*H$19*$B$4)/1000000)/$B$5 -> 0.26744186 | I21: =(($C$10*I$19+$D$10*I$19*$B$4)/1000000)/$B$5 -> 0.53488372 | ... L21: =(($C$10*L$19+$D$10*L$19*$B$4)/1000000)/$B$5 -> 2.6744186 | M21: =B10 -> 36.593407
A22: ='Process Comparison'!A11 -> Fraud Alert Triage | B22: =(($C$11*B$19+$D$11*B$19*$B$4)/1000000)/$B$5 -> 0.0012403101 | C22: =(($C$11*C$19+$D$11*C$19*$B$4)/1000000)/$B$5 -> 0.0031007752 | D22: =(($C$11*D$19+$D$11*D$19*$B$4)/1000000)/$B$5 -> 0.0062015504 | E22: =(($C$11*E$19+$D$11*E$19*$B$4)/1000000)/$B$5 -> 0.012403101 | F22: =(($C$11*F$19+$D$11*F$19*$B$4)/1000000)/$B$5 -> 0.024806202 | G22: =(($C$11*G$19+$D$11*G$19*$B$4)/1000000)/$B$5 -> 0.037209302 | H22: =(($C$11*H$19+$D$11*H$19*$B$4)/1000000)/$B$5 -> 0.062015504 | I22: =(($C$11*I$19+$D$11*I$19*$B$4)/1000000)/$B$5 -> 0.12403101 | ... L22: =(($C$11*L$19+$D$11*L$19*$B$4)/1000000)/$B$5 -> 0.62015504 | M22: =B11 -> 4.3369963
A23: ='Process Comparison'!A12 -> Mortgage Application Review | B23: =(($C$12*B$19+$D$12*B$19*$B$4)/1000000)/$B$5 -> 0.011627907 | C23: =(($C$12*C$19+$D$12*C$19*$B$4)/1000000)/$B$5 -> 0.029069767 | D23: =(($C$12*D$19+$D$12*D$19*$B$4)/1000000)/$B$5 -> 0.058139535 | E23: =(($C$12*E$19+$D$12*E$19*$B$4)/1000000)/$B$5 -> 0.11627907 | F23: =(($C$12*F$19+$D$12*F$19*$B$4)/1000000)/$B$5 -> 0.23255814 | G23: =(($C$12*G$19+$D$12*G$19*$B$4)/1000000)/$B$5 -> 0.34883721 | H23: =(($C$12*H$19+$D$12*H$19*$B$4)/1000000)/$B$5 -> 0.58139535 | I23: =(($C$12*I$19+$D$12*I$19*$B$4)/1000000)/$B$5 -> 1.1627907 | ... L23: =(($C$12*L$19+$D$12*L$19*$B$4)/1000000)/$B$5 -> 5.8139535 | M23: =B12 -> 63.021978
A24: ='Process Comparison'!A13 -> Customer Complaint Resolution | B24: =(($C$13*B$19+$D$13*B$19*$B$4)/1000000)/$B$5 -> 0.0028682171 | C24: =(($C$13*C$19+$D$13*C$19*$B$4)/1000000)/$B$5 -> 0.0071705426 | D24: =(($C$13*D$19+$D$13*D$19*$B$4)/1000000)/$B$5 -> 0.014341085 | E24: =(($C$13*E$19+$D$13*E$19*$B$4)/1000000)/$B$5 -> 0.028682171 | F24: =(($C$13*F$19+$D$13*F$19*$B$4)/1000000)/$B$5 -> 0.057364341 | G24: =(($C$13*G$19+$D$13*G$19*$B$4)/1000000)/$B$5 -> 0.086046512 | H24: =(($C$13*H$19+$D$13*H$19*$B$4)/1000000)/$B$5 -> 0.14341085 | I24: =(($C$13*I$19+$D$13*I$19*$B$4)/1000000)/$B$5 -> 0.28682171 | ... L24: =(($C$13*L$19+$D$13*L$19*$B$4)/1000000)/$B$5 -> 1.4341085 | M24: =B13 -> 28.461538
A25: ='Process Comparison'!A14 -> Regulatory Document Review | B25: =(($C$14*B$19+$D$14*B$19*$B$4)/1000000)/$B$5 -> 0.0093023256 | C25: =(($C$14*C$19+$D$14*C$19*$B$4)/1000000)/$B$5 -> 0.023255814 | D25: =(($C$14*D$19+$D$14*D$19*$B$4)/1000000)/$B$5 -> 0.046511628 | E25: =(($C$14*E$19+$D$14*E$19*$B$4)/1000000)/$B$5 -> 0.093023256 | F25: =(($C$14*F$19+$D$14*F$19*$B$4)/1000000)/$B$5 -> 0.18604651 | G25: =(($C$14*G$19+$D$14*G$19*$B$4)/1000000)/$B$5 -> 0.27906977 | H25: =(($C$14*H$19+$D$14*H$19*$B$4)/1000000)/$B$5 -> 0.46511628 | I25: =(($C$14*I$19+$D$14*I$19*$B$4)/1000000)/$B$5 -> 0.93023256 | ... L25: =(($C$14*L$19+$D$14*L$19*$B$4)/1000000)/$B$5 -> 4.6511628 | M25: =B14 -> 86.126374
A26: ='Process Comparison'!A15 -> MI / Management Reporting | B26: =(($C$15*B$19+$D$15*B$19*$B$4)/1000000)/$B$5 -> 0.0062015504 | C26: =(($C$15*C$19+$D$15*C$19*$B$4)/1000000)/$B$5 -> 0.015503876 | D26: =(($C$15*D$19+$D$15*D$19*$B$4)/1000000)/$B$5 -> 0.031007752 | E26: =(($C$15*E$19+$D$15*E$19*$B$4)/1000000)/$B$5 -> 0.062015504 | F26: =(($C$15*F$19+$D$15*F$19*$B$4)/1000000)/$B$5 -> 0.12403101 | G26: =(($C$15*G$19+$D$15*G$19*$B$4)/1000000)/$B$5 -> 0.18604651 | H26: =(($C$15*H$19+$D$15*H$19*$B$4)/1000000)/$B$5 -> 0.31007752 | I26: =(($C$15*I$19+$D$15*I$19*$B$4)/1000000)/$B$5 -> 0.62015504 | ... L26: =(($C$15*L$19+$D$15*L$19*$B$4)/1000000)/$B$5 -> 3.1007752 | M26: =B15 -> 97.582418

Sheet Volume Scaling
A1: Annual Volume Scaling: Cost at Scale
A2: Scales per-task economics to annual volumes. Yellow cells are editable.
A4: Business Process | B4: Est. Annual Volume | C4: Human FTEs Required | D4: Annual Human Cost (£) | E4: Annual AI Solo Cost (£) | F4: Annual Hybrid Cost (£) | G4: Annual Saving: AI Solo (£) | H4: Annual Saving: Hybrid (£) | I4: FTEs Freed: AI Solo | J4: FTEs Freed: Hybrid
A5: ='Process Comparison'!A10 -> KYC / Onboarding Check | B5: 50000 | C5: =(B5*'Process Comparison'!C10)/(1820*60) -> 20.604396 | D5: =B5*'Process Comparison'!D10 -> 1829670.3 | E5: =B5*'Process Comparison'!K10 -> 282473.81 | F5: =B5*'Process Comparison'!L10 -> 465440.84 | G5: =D5-E5 -> 1547196.5 | H5: =D5-F5 -> 1364229.5 | I5: =IF(D5=0,0,C5*(1-E5/D5)) -> 17.423384 | J5: =IF(D5=0,0,C5*(1-F5/D5)) -> 15.362945
A6: ='Process Comparison'!A11 -> Fraud Alert Triage | B6: 200000 | C6: =(B6*'Process Comparison'!C11)/(1820*60) -> 14.652015 | D6: =B6*'Process Comparison'!D11 -> 867399.27 | E6: =B6*'Process Comparison'!K11 -> 94181.787 | F6: =B6*'Process Comparison'!L11 -> 180921.71 | G6: =D6-E6 -> 773217.48 | H6: =D6-F6 -> 686477.55 | I6: =IF(D6=0,0,C6*(1-E6/D6)) -> 13.061106 | J6: =IF(D6=0,0,C6*(1-F6/D6)) -> 11.595905
A7: ='Process Comparison'!A12 -> Mortgage Application Review | B7: 15000 | C7: =(B7*'Process Comparison'!C12)/(1820*60) -> 8.2417582 | D7: =B7*'Process Comparison'!D12 -> 945329.67 | E7: =B7*'Process Comparison'!K12 -> 288831.46 | F7: =B7*'Process Comparison'!L12 -> 336097.94 | G7: =D7-E7 -> 656498.21 | H7: =D7-F7 -> 609231.73 | I7: =IF(D7=0,0,C7*(1-E7/D7)) -> 5.7236113 | J7: =IF(D7=0,0,C7*(1-F7/D7)) -> 5.3115233
A8: ='Process Comparison'!A13 -> Customer Complaint Resolution | B8: 80000 | C8: =(B8*'Process Comparison'!C13)/(1820*60) -> 25.641026 | D8: =B8*'Process Comparison'!D13 -> 2276923.1 | E8: =B8*'Process Comparison'!K13 -> 803806.8 | F8: =B8*'Process Comparison'!L13 -> 917652.95 | G8: =D8-E8 -> 1473116.3 | H8: =D8-F8 -> 1359270.1 | I8: =IF(D8=0,0,C8*(1-E8/D8)) -> 16.589147 | J8: =IF(D8=0,0,C8*(1-F8/D8)) -> 15.307096
A9: ='Process Comparison'!A14 -> Regulatory Document Review | B9: 5000 | C9: =(B9*'Process Comparison'!C14)/(1820*60) -> 4.1208791 | D9: =B9*'Process Comparison'!D14 -> 430631.87 | E9: =B9*'Process Comparison'!K14 -> 109053.32 | F9: =B9*'Process Comparison'!L14 -> 130584.91 | G9: =D9-E9 -> 321578.55 | H9: =D9-F9 -> 300046.96 | I9: =IF(D9=0,0,C9*(1-E9/D9)) -> 3.0773067 | J9: =IF(D9=0,0,C9*(1-F9/D9)) -> 2.8712628
A10: ='Process Comparison'!A15 -> MI / Management Reporting | B10: 2000 | C10: =(B10*'Process Comparison'!C15)/(1820*60) -> 2.1978022 | D10: =B10*'Process Comparison'!D15 -> 195164.84 | E10: =B10*'Process Comparison'!K15 -> 19888.577 | F10: =B10*'Process Comparison'!L15 -> 29646.818 | G10: =D10-E10 -> 175276.26 | H10: =D10-F10 -> 165518.02 | I10: =IF(D10=0,0,C10*(1-E10/D10)) -> 1.9738317 | J10: =IF(D10=0,0,C10*(1-F10/D10)) -> 1.8639416
A11: TOTAL | B11: =SUM(B5:B10) -> 352000 | C11: =SUM(C5:C10) -> 75.457875 | D11: =SUM(D5:D10) -> 6545119 | E11: =SUM(E5:E10) -> 1598235.7 | F11: =SUM(F5:F10) -> 2060345.2 | G11: =SUM(G5:G10) -> 4946883.3 | H11: =SUM(H5:H10) -> 4484773.9 | I11: =SUM(I5:I10) -> 57.848387 | J11: =SUM(J5:J10) -> 52.312673

Sheet Price Trajectory
A1: Token Price Trajectory and Future Projections
A2: Historical trend: roughly 40-50% cost reduction annually. What does this mean for the economics?
A4: Annual price decline rate: | B4: 0.4
B6: Today (Mar 2026) | C6: 2027 | D6: 2028 | E6: 2029 | F6: 2030
A7: Sonnet-tier Input ($/MTok) | B7: 3 | C7: =B7*(1-$B$4) -> 1.8 | D7: =C7*(1-$B$4) -> 1.08 | E7: =D7*(1-$B$4) -> 0.648 | F7: =E7*(1-$B$4) -> 0.3888
A8: Sonnet-tier Output ($/MTok) | B8: 15 | C8: =B8*(1-$B$4) -> 9 | D8: =C8*(1-$B$4) -> 5.4 | E8: =D8*(1-$B$4) -> 3.24 | F8: =E8*(1-$B$4) -> 1.944
A10: AI Token Cost per Task (£) Over Time
A11: Business Process | B11: Today | C11: 2027 | D11: 2028 | E11: 2029 | F11: 2030
A12: ='Process Comparison'!A10 -> KYC / Onboarding Check | B12: ='Process Comparison'!J10 -> 0.16046512 | C12: =B12*(1-$B$4)^1 -> 0.09627907 | D12: =B12*(1-$B$4)^2 -> 0.057767442 | E12: =B12*(1-$B$4)^3 -> 0.034660465 | F12: =B12*(1-$B$4)^4 -> 0.020796279
A13: ='Process Comparison'!A11 -> Fraud Alert Triage | B13: ='Process Comparison'!J11 -> 0.037209302 | C13: =B13*(1-$B$4)^1 -> 0.022325581 | D13: =B13*(1-$B$4)^2 -> 0.013395349 | E13: =B13*(1-$B$4)^3 -> 0.0080372093 | F13: =B13*(1-$B$4)^4 -> 0.0048223256
A14: ='Process Comparison'!A12 -> Mortgage Application Review | B14: ='Process Comparison'!J12 -> 0.34883721 | C14: =B14*(1-$B$4)^1 -> 0.20930233 | D14: =B14*(1-$B$4)^2 -> 0.1255814 | E14: =B14*(1-$B$4)^3 -> 0.075348837 | F14: =B14*(1-$B$4)^4 -> 0.045209302
A15: ='Process Comparison'!A13 -> Customer Complaint Resolution | B15: ='Process Comparison'!J13 -> 0.086046512 | C15: =B15*(1-$B$4)^1 -> 0.051627907 | D15: =B15*(1-$B$4)^2 -> 0.030976744 | E15: =B15*(1-$B$4)^3 -> 0.018586047 | F15: =B15*(1-$B$4)^4 -> 0.011151628
A16: ='Process Comparison'!A14 -> Regulatory Document Review | B16: ='Process Comparison'!J14 -> 0.27906977 | C16: =B16*(1-$B$4)^1 -> 0.16744186 | D16: =B16*(1-$B$4)^2 -> 0.10046512 | E16: =B16*(1-$B$4)^3 -> 0.06027907 | F16: =B16*(1-$B$4)^4 -> 0.036167442
A17: ='Process Comparison'!A15 -> MI / Management Reporting | B17: ='Process Comparison'!J15 -> 0.18604651 | C17: =B17*(1-$B$4)^1 -> 0.11162791 | D17: =B17*(1-$B$4)^2 -> 0.066976744 | E17: =B17*(1-$B$4)^3 -> 0.040186047 | F17: =B17*(1-$B$4)^4 -> 0.024111628

Sheet Model Comparison
A1: Cost per Task by Model: Which Model for Which Process?
A2: Shows token cost only (not residual human cost). Greyed out where model capability is rated below deployment threshold. | B2: 5 | C2: 2.5 | D2: 0.4 | E2: 4.4 | F2: 0.42 | G2: 1.5 | H2: 15 | I2: 10 | J2: 12 | K2: 15 | L2: 2.19 | M2: 25 | N2: 15
B3: 1 | C3: 0.3 | D3: 0.1 | E3: 1.1 | F3: 0.28 | G3: 0.5 | H3: 3 | I3: 2.5 | J3: 2 | K3: 3 | L3: 0.55 | M3: 5 | N3: 2.5
A4: Business Process | B4: Haiku 4.5 | C4: Gemini Flash | D4: Flash-Lite | E4: o4-mini | F4: DeepSeek V4 | G4: Mistral L3 | H4: Sonnet 4.6 | I4: GPT-4o | J4: Gemini 3.1P | K4: Grok 4 | L4: DeepSeek R2 | M4: Opus 4.6 | N4: GPT-5.4 | O4: Human Cost (£)
A5: ='Process Comparison'!A10 -> KYC / Onboarding Check | B5: =(('Process Comparison'!G10*B$3+'Process Comparison'!H10*B$2)/1000000)*'Process Comparison'!I10/Assumptions!$B$27 -> 0.053488372 | C5: =(('Process Comparison'!G10*C$3+'Process Comparison'!H10*C$2)/1000000)*'Process Comparison'!I10/Assumptions!$B$27 -> 0.023023256 | D5: =(('Process Comparison'!G10*D$3+'Process Comparison'!H10*D$2)/1000000)*'Process Comparison'!I10/Assumptions!$B$27 -> 0.0046511628 | E5: =(('Process Comparison'!G10*E$3+'Process Comparison'!H10*E$2)/1000000)*'Process Comparison'!I10/Assumptions!$B$27 -> 0.051162791 | F5: =(('Process Comparison'!G10*F$3+'Process Comparison'!H10*F$2)/1000000)*'Process Comparison'!I10/Assumptions!$B$27 -> 0.0081395349 | G5: =(('Process Comparison'!G10*G$3+'Process Comparison'!H10*G$2)/1000000)*'Process Comparison'!I10/Assumptions!$B$27 -> 0.019767442 | H5: =(('Process Comparison'!G10*H$3+'Process Comparison'!H10*H$2)/1000000)*'Process Comparison'!I10/Assumptions!$B$27 -> 0.16046512 | I5: =(('Process Comparison'!G10*I$3+'Process Comparison'!H10*I$2)/1000000)*'Process Comparison'!I10/Assumptions!$B$27 -> 0.11627907 | J5: =(('Process Comparison'!G10*J$3+'Process Comparison'!H10*J$2)/1000000)*'Process Comparison'!I10/Assumptions!$B$27 -> 0.12093023 | K5: =(('Process Comparison'!G10*K$3+'Process Comparison'!H10*K$2)/1000000)*'Process Comparison'!I10/Assumptions!$B$27 -> 0.16046512 | L5: =(('Process Comparison'!G10*L$3+'Process Comparison'!H10*L$2)/1000000)*'Process Comparison'!I10/Assumptions!$B$27 -> 0.025511628 | M5: =(('Process Comparison'!G10*M$3+'Process Comparison'!H10*M$2)/1000000)*'Process Comparison'!I10/Assumptions!$B$27 -> 0.26744186 | N5: =(('Process Comparison'!G10*N$3+'Process Comparison'!H10*N$2)/1000000)*'Process Comparison'!I10/Assumptions!$B$27 -> 0.15116279 | O5: ='Process Comparison'!D10 -> 36.593407
A6: ='Process Comparison'!A11 -> Fraud Alert Triage | B6: =(('Process Comparison'!G11*B$3+'Process Comparison'!H11*B$2)/1000000)*'Process Comparison'!I11/Assumptions!$B$27 -> 0.012403101 | C6: =(('Process Comparison'!G11*C$3+'Process Comparison'!H11*C$2)/1000000)*'Process Comparison'!I11/Assumptions!$B$27 -> 0.0052713178 | D6: =(('Process Comparison'!G11*D$3+'Process Comparison'!H11*D$2)/1000000)*'Process Comparison'!I11/Assumptions!$B$27 -> 0.0010852713 | E6: =(('Process Comparison'!G11*E$3+'Process Comparison'!H11*E$2)/1000000)*'Process Comparison'!I11/Assumptions!$B$27 -> 0.011937984 | F6: =(('Process Comparison'!G11*F$3+'Process Comparison'!H11*F$2)/1000000)*'Process Comparison'!I11/Assumptions!$B$27 -> 0.0019534884 | G6: =(('Process Comparison'!G11*G$3+'Process Comparison'!H11*G$2)/1000000)*'Process Comparison'!I11/Assumptions!$B$27 -> 0.0046511628 | H6: =(('Process Comparison'!G11*H$3+'Process Comparison'!H11*H$2)/1000000)*'Process Comparison'!I11/Assumptions!$B$27 -> 0.037209302 | I6: =(('Process Comparison'!G11*I$3+'Process Comparison'!H11*I$2)/1000000)*'Process Comparison'!I11/Assumptions!$B$27 -> 0.027131783 | J6: =(('Process Comparison'!G11*J$3+'Process Comparison'!H11*J$2)/1000000)*'Process Comparison'!I11/Assumptions!$B$27 -> 0.027906977 | K6: =(('Process Comparison'!G11*K$3+'Process Comparison'!H11*K$2)/1000000)*'Process Comparison'!I11/Assumptions!$B$27 -> 0.037209302 | L6: =(('Process Comparison'!G11*L$3+'Process Comparison'!H11*L$2)/1000000)*'Process Comparison'!I11/Assumptions!$B$27 -> 0.0059534884 | M6: =(('Process Comparison'!G11*M$3+'Process Comparison'!H11*M$2)/1000000)*'Process Comparison'!I11/Assumptions!$B$27 -> 0.062015504 | N6: =(('Process Comparison'!G11*N$3+'Process Comparison'!H11*N$2)/1000000)*'Process Comparison'!I11/Assumptions!$B$27 -> 0.034883721 | O6: ='Process Comparison'!D11 -> 4.3369963
A7: ='Process Comparison'!A12 -> Mortgage Application Review | B7: =(('Process Comparison'!G12*B$3+'Process Comparison'!H12*B$2)/1000000)*'Process Comparison'!I12/Assumptions!$B$27 -> 0.11627907 | C7: =(('Process Comparison'!G12*C$3+'Process Comparison'!H12*C$2)/1000000)*'Process Comparison'!I12/Assumptions!$B$27 -> 0.050387597 | D7: =(('Process Comparison'!G12*D$3+'Process Comparison'!H12*D$2)/1000000)*'Process Comparison'!I12/Assumptions!$B$27 -> 0.010077519 | E7: =(('Process Comparison'!G12*E$3+'Process Comparison'!H12*E$2)/1000000)*'Process Comparison'!I12/Assumptions!$B$27 -> 0.11085271 | F7: =(('Process Comparison'!G12*F$3+'Process Comparison'!H12*F$2)/1000000)*'Process Comparison'!I12/Assumptions!$B$27 -> 0.017364341 | G7: =(('Process Comparison'!G12*G$3+'Process Comparison'!H12*G$2)/1000000)*'Process Comparison'!I12/Assumptions!$B$27 -> 0.042635659 | H7: =(('Process Comparison'!G12*H$3+'Process Comparison'!H12*H$2)/1000000)*'Process Comparison'!I12/Assumptions!$B$27 -> 0.34883721 | I7: =(('Process Comparison'!G12*I$3+'Process Comparison'!H12*I$2)/1000000)*'Process Comparison'!I12/Assumptions!$B$27 -> 0.25193798 | J7: =(('Process Comparison'!G12*J$3+'Process Comparison'!H12*J$2)/1000000)*'Process Comparison'!I12/Assumptions!$B$27 -> 0.26356589 | K7: =(('Process Comparison'!G12*K$3+'Process Comparison'!H12*K$2)/1000000)*'Process Comparison'!I12/Assumptions!$B$27 -> 0.34883721 | L7: =(('Process Comparison'!G12*L$3+'Process Comparison'!H12*L$2)/1000000)*'Process Comparison'!I12/Assumptions!$B$27 -> 0.055271318 | M7: =(('Process Comparison'!G12*M$3+'Process Comparison'!H12*M$2)/1000000)*'Process Comparison'!I12/Assumptions!$B$27 -> 0.58139535 | N7: =(('Process Comparison'!G12*N$3+'Process Comparison'!H12*N$2)/1000000)*'Process Comparison'!I12/Assumptions!$B$27 -> 0.32945736 | O7: ='Process Comparison'!D12 -> 63.021978
A8: ='Process Comparison'!A13 -> Customer Complaint Resolution | B8: =(('Process Comparison'!G13*B$3+'Process Comparison'!H13*B$2)/1000000)*'Process Comparison'!I13/Assumptions!$B$27 -> 0.028682171 | C8: =(('Process Comparison'!G13*C$3+'Process Comparison'!H13*C$2)/1000000)*'Process Comparison'!I13/Assumptions!$B$27 -> 0.01248062 | D8: =(('Process Comparison'!G13*D$3+'Process Comparison'!H13*D$2)/1000000)*'Process Comparison'!I13/Assumptions!$B$27 -> 0.0024806202 | E8: =(('Process Comparison'!G13*E$3+'Process Comparison'!H13*E$2)/1000000)*'Process Comparison'!I13/Assumptions!$B$27 -> 0.027286822 | F8: =(('Process Comparison'!G13*F$3+'Process Comparison'!H13*F$2)/1000000)*'Process Comparison'!I13/Assumptions!$B$27 -> 0.0042325581 | G8: =(('Process Comparison'!G13*G$3+'Process Comparison'!H13*G$2)/1000000)*'Process Comparison'!I13/Assumptions!$B$27 -> 0.010465116 | H8: =(('Process Comparison'!G13*H$3+'Process Comparison'!H13*H$2)/1000000)*'Process Comparison'!I13/Assumptions!$B$27 -> 0.086046512 | I8: =(('Process Comparison'!G13*I$3+'Process Comparison'!H13*I$2)/1000000)*'Process Comparison'!I13/Assumptions!$B$27 -> 0.062015504 | J8: =(('Process Comparison'!G13*J$3+'Process Comparison'!H13*J$2)/1000000)*'Process Comparison'!I13/Assumptions!$B$27 -> 0.065116279 | K8: =(('Process Comparison'!G13*K$3+'Process Comparison'!H13*K$2)/1000000)*'Process Comparison'!I13/Assumptions!$B$27 -> 0.086046512 | L8: =(('Process Comparison'!G13*L$3+'Process Comparison'!H13*L$2)/1000000)*'Process Comparison'!I13/Assumptions!$B$27 -> 0.013604651 | M8: =(('Process Comparison'!G13*M$3+'Process Comparison'!H13*M$2)/1000000)*'Process Comparison'!I13/Assumptions!$B$27 -> 0.14341085 | N8: =(('Process Comparison'!G13*N$3+'Process Comparison'!H13*N$2)/1000000)*'Process Comparison'!I13/Assumptions!$B$27 -> 0.081395349 | O8: ='Process Comparison'!D13 -> 28.461538
A9: ='Process Comparison'!A14 -> Regulatory Document Review | B9: =(('Process Comparison'!G14*B$3+'Process Comparison'!H14*B$2)/1000000)*'Process Comparison'!I14/Assumptions!$B$27 -> 0.093023256 | C9: =(('Process Comparison'!G14*C$3+'Process Comparison'!H14*C$2)/1000000)*'Process Comparison'!I14/Assumptions!$B$27 -> 0.039534884 | D9: =(('Process Comparison'!G14*D$3+'Process Comparison'!H14*D$2)/1000000)*'Process Comparison'!I14/Assumptions!$B$27 -> 0.0081395349 | E9: =(('Process Comparison'!G14*E$3+'Process Comparison'!H14*E$2)/1000000)*'Process Comparison'!I14/Assumptions!$B$27 -> 0.089534884 | F9: =(('Process Comparison'!G14*F$3+'Process Comparison'!H14*F$2)/1000000)*'Process Comparison'!I14/Assumptions!$B$27 -> 0.014651163 | G9: =(('Process Comparison'!G14*G$3+'Process Comparison'!H14*G$2)/1000000)*'Process Comparison'!I14/Assumptions!$B$27 -> 0.034883721 | H9: =(('Process Comparison'!G14*H$3+'Process Comparison'!H14*H$2)/1000000)*'Process Comparison'!I14/Assumptions!$B$27 -> 0.27906977 | I9: =(('Process Comparison'!G14*I$3+'Process Comparison'!H14*I$2)/1000000)*'Process Comparison'!I14/Assumptions!$B$27 -> 0.20348837 | J9: =(('Process Comparison'!G14*J$3+'Process Comparison'!H14*J$2)/1000000)*'Process Comparison'!I14/Assumptions!$B$27 -> 0.20930233 | K9: =(('Process Comparison'!G14*K$3+'Process Comparison'!H14*K$2)/1000000)*'Process Comparison'!I14/Assumptions!$B$27 -> 0.27906977 | L9: =(('Process Comparison'!G14*L$3+'Process Comparison'!H14*L$2)/1000000)*'Process Comparison'!I14/Assumptions!$B$27 -> 0.044651163 | M9: =(('Process Comparison'!G14*M$3+'Process Comparison'!H14*M$2)/1000000)*'Process Comparison'!I14/Assumptions!$B$27 -> 0.46511628 | N9: =(('Process Comparison'!G14*N$3+'Process Comparison'!H14*N$2)/1000000)*'Process Comparison'!I14/Assumptions!$B$27 -> 0.26162791 | O9: ='Process Comparison'!D14 -> 86.126374
A10: ='Process Comparison'!A15 -> MI / Management Reporting | B10: =(('Process Comparison'!G15*B$3+'Process Comparison'!H15*B$2)/1000000)*'Process Comparison'!I15/Assumptions!$B$27 -> 0.062015504 | C10: =(('Process Comparison'!G15*C$3+'Process Comparison'!H15*C$2)/1000000)*'Process Comparison'!I15/Assumptions!$B$27 -> 0.027906977 | D10: =(('Process Comparison'!G15*D$3+'Process Comparison'!H15*D$2)/1000000)*'Process Comparison'!I15/Assumptions!$B$27 -> 0.0052713178 | E10: =(('Process Comparison'!G15*E$3+'Process Comparison'!H15*E$2)/1000000)*'Process Comparison'!I15/Assumptions!$B$27 -> 0.057984496 | F10: =(('Process Comparison'!G15*F$3+'Process Comparison'!H15*F$2)/1000000)*'Process Comparison'!I15/Assumptions!$B$27 -> 0.008248062 | G10: =(('Process Comparison'!G15*G$3+'Process Comparison'!H15*G$2)/1000000)*'Process Comparison'!I15/Assumptions!$B$27 -> 0.021705426 | H10: =(('Process Comparison'!G15*H$3+'Process Comparison'!H15*H$2)/1000000)*'Process Comparison'!I15/Assumptions!$B$27 -> 0.18604651 | I10: =(('Process Comparison'!G15*I$3+'Process Comparison'!H15*I$2)/1000000)*'Process Comparison'!I15/Assumptions!$B$27 -> 0.13178295 | J10: =(('Process Comparison'!G15*J$3+'Process Comparison'!H15*J$2)/1000000)*'Process Comparison'!I15/Assumptions!$B$27 -> 0.14263566 | K10: =(('Process Comparison'!G15*K$3+'Process Comparison'!H15*K$2)/1000000)*'Process Comparison'!I15/Assumptions!$B$27 -> 0.18604651 | L10: =(('Process Comparison'!G15*L$3+'Process Comparison'!H15*L$2)/1000000)*'Process Comparison'!I15/Assumptions!$B$27 -> 0.028899225 | M10: =(('Process Comparison'!G15*M$3+'Process Comparison'!H15*M$2)/1000000)*'Process Comparison'!I15/Assumptions!$B$27 -> 0.31007752 | N10: =(('Process Comparison'!G15*N$3+'Process Comparison'!H15*N$2)/1000000)*'Process Comparison'!I15/Assumptions!$B$27 -> 0.17829457 | O10: ='Process Comparison'!D15 -> 97.582418
