Workbook

Sheet Assumptions
A1: The Agentic Economy: Input Assumptions
A3: 1. Fully Loaded FTE Costs
B4: Average base salary (GBP) | C4: 55000 | D4: UK banking average, adjust per grade
B5: Fully loaded multiplier | C5: 1.9 | D5: Benefits, NI, pension, office, management overhead
B6: Fully loaded FTE cost (GBP) | C6: =C4*C5 -> 104500 | D6: Annual cost per FTE
B7: Productive hours per year | C7: 1540 | D7: 52 weeks less holiday, sick, training
B8: Effective hourly rate (GBP) | C8: =C6/C7 -> 67.857143 | D8: Fully loaded
B9: Average tasks per hour (human) | C9: 4 | D9: Varies significantly by process
B10: Cost per task (human, GBP) | C10: =C8/C9 -> 16.964286
A12: 2. AI Agent Costs
B13: Average input token price (per 1M tokens, GBP) | C13: 2.5 | D13: Blended across models used
B14: Average output token price (per 1M tokens, GBP) | C14: 10 | D14: Blended across models used
B15: Average input tokens per task | C15: 2000 | D15: Prompt + context
B16: Average output tokens per task | C16: 500 | D16: Agent response
B17: Cost per task (AI agent, GBP) | C17: =(C15/1000000*C13)+(C16/1000000*C14) -> 0.01 | D17: Pure inference cost
B18: Orchestration & infra overhead (%) | C18: 0.35 | D18: Monitoring, error handling, logging
B19: Fully loaded cost per task (AI, GBP) | C19: =C17*(1+C18) -> 0.0135 | D19: Including infrastructure
B20: AI tasks per hour | C20: 120 | D20: Throughput per agent instance
B21: Annual token price decline rate | C21: 0.4 | D21: Historical: 40-70% per annum
A23: 3. Error Costs and Oversight
B24: Human error rate (%) | C24: 0.02 | D24: Baseline: 2% across processes
B25: AI error rate (%) | C25: 0.05 | D25: Current estimate, varies by task
B26: Average cost per error (GBP) | C26: 500 | D26: Financial + reputational + remediation
B27: Human oversight requirement (%) | C27: 0.15 | D27: % of AI tasks requiring human review
B28: Time per oversight review (minutes) | C28: 5 | D28: Average review duration
B29: Oversight cost per AI task (GBP) | C29: =C27*(C28/60)*C8 -> 0.84821429 | D29: Derived from hourly rate
B30: Total AI cost per task incl errors & oversight (GBP) | C30: =C19+(C25*C26)+C29 -> 25.861714
B31: Total human cost per task incl errors (GBP) | C31: =C10+(C24*C26) -> 26.964286
A33: 4. Token Consumption Benchmarks
B34: Huang benchmark (tokens as % of salary) | C34: 0.5 | D34: Jensen Huang: 50% of engineer salary
B35: Implied annual token budget per FTE (GBP) | C35: =C4*C34 -> 27500
B36: a16z baseline (annual per engineer, GBP) | C36: 6700 | D36: a16z recommendation ~$8,000
B37: Current bank AI spend per FTE (GBP) | C37: 800 | D37: Estimated current state
B38: Gap to Huang benchmark (GBP) | C38: =C35-C37 -> 26700
B39: Gap to a16z baseline (GBP) | C39: =C36-C37 -> 5900
B40: Total FTE headcount | C40: 60000 | D40: Approximate bank headcount
B41: Annual token spend at Huang benchmark (GBP m) | C41: =C35*C40/1000000 -> 1650
B42: Annual token spend at a16z baseline (GBP m) | C42: =C36*C40/1000000 -> 402
B43: Current annual AI spend (GBP m) | C43: =C37*C40/1000000 -> 48
A45: 5. Balance Sheet and Accounting
...

Sheet Process Comparison
A1: Process-Level Comparison: Human vs AI Agent
A3: Input: Automatability by Process (editable)
B4: Process | C4: Annual Volume | D4: Automatability % | E4: FTEs Today | F4: Human Cost/Task | G4: AI Cost/Task | H4: Blended Cost/Task | I4: Annual Saving (GBP) | J4: Saving %
B5: Transaction Monitoring | C5: 5000000 | D5: 0.7 | E5: 120 | F5: =Assumptions!C31 -> 26.964286 | G5: =Assumptions!C30 -> 25.861714 | H5: =(D5*G5)+((1-D5)*F5) -> 26.192486 | I5: =C5*(F5-H5) -> 3859000 | J5: =IF(F5=0,0,I5/(C5*F5)) -> 0.028623046
B6: KYC / Onboarding | C6: 800000 | D6: 0.55 | E6: 200 | F6: =Assumptions!C31 -> 26.964286 | G6: =Assumptions!C30 -> 25.861714 | H6: =(D6*G6)+((1-D6)*F6) -> 26.357871 | I6: =C6*(F6-H6) -> 485131.43 | J6: =IF(F6=0,0,I6/(C6*F6)) -> 0.022489536
B7: Credit Decisioning | C7: 1200000 | D7: 0.45 | E7: 180 | F7: =Assumptions!C31 -> 26.964286 | G7: =Assumptions!C30 -> 25.861714 | H7: =(D7*G7)+((1-D7)*F7) -> 26.468129 | I7: =C7*(F7-H7) -> 595388.57 | J7: =IF(F7=0,0,I7/(C7*F7)) -> 0.01840053
B8: Complaints Handling | C8: 600000 | D8: 0.4 | E8: 150 | F8: =Assumptions!C31 -> 26.964286 | G8: =Assumptions!C30 -> 25.861714 | H8: =(D8*G8)+((1-D8)*F8) -> 26.523257 | I8: =C8*(F8-H8) -> 264617.14 | J8: =IF(F8=0,0,I8/(C8*F8)) -> 0.016356026
B9: Fraud Investigation | C9: 400000 | D9: 0.35 | E9: 80 | F9: =Assumptions!C31 -> 26.964286 | G9: =Assumptions!C30 -> 25.861714 | H9: =(D9*G9)+((1-D9)*F9) -> 26.578386 | I9: =C9*(F9-H9) -> 154360 | J9: =IF(F9=0,0,I9/(C9*F9)) -> 0.014311523
B10: Regulatory Reporting | C10: 200000 | D10: 0.6 | E10: 60 | F10: =Assumptions!C31 -> 26.964286 | G10: =Assumptions!C30 -> 25.861714 | H10: =(D10*G10)+((1-D10)*F10) -> 26.302743 | I10: =C10*(F10-H10) -> 132308.57 | J10: =IF(F10=0,0,I10/(C10*F10)) -> 0.02453404
B11: Mortgage Processing | C11: 350000 | D11: 0.5 | E11: 250 | F11: =Assumptions!C31 -> 26.964286 | G11: =Assumptions!C30 -> 25.861714 | H11: =(D11*G11)+((1-D11)*F11) -> 26.413 | I11: =C11*(F11-H11) -> 192950 | J11: =IF(F11=0,0,I11/(C11*F11)) -> 0.020445033
B12: Customer Service (L1) | C12: 8000000 | D12: 0.75 | E12: 500 | F12: =Assumptions!C31 -> 26.964286 | G12: =Assumptions!C30 -> 25.861714 | H12: =(D12*G12)+((1-D12)*F12) -> 26.137357 | I12: =C12*(F12-H12) -> 6615428.6 | J12: =IF(F12=0,0,I12/(C12*F12)) -> 0.03066755
B13: Internal Audit Prep | C13: 50000 | D13: 0.3 | E13: 40 | F13: =Assumptions!C31 -> 26.964286 | G13: =Assumptions!C30 -> 25.861714 | H13: =(D13*G13)+((1-D13)*F13) -> 26.633514 | I13: =C13*(F13-H13) -> 16538.571 | J13: =IF(F13=0,0,I13/(C13*F13)) -> 0.01226702
B14: Procurement / Vendor Mgmt | C14: 100000 | D14: 0.45 | E14: 30 | F14: =Assumptions!C31 -> 26.964286 | G14: =Assumptions!C30 -> 25.861714 | H14: =(D14*G14)+((1-D14)*F14) -> 26.468129 | I14: =C14*(F14-H14) -> 49615.714 | J14: =IF(F14=0,0,I14/(C14*F14)) -> 0.01840053
B15: TOTAL | C15: =SUM(C5:C14) -> 16700000 | E15: =SUM(E5:E14) -> 1610 | I15: =SUM(I5:I14) -> 12365339 | J15: =IF(SUMPRODUCT(C5:C14,F5:F14)=0,0,I15/SUMPRODUCT(C5:C14,F5:F14)) -> 0.027460006
A17: Implied FTE Displacement
B18: Process | C18: FTEs Today | D18: Automatability % | E18: Implied FTE Reduction | F18: Remaining FTEs
B19: =B5 -> Transaction Monitoring | C19: =E5 -> 120 | D19: =D5 -> 0.7 | E19: =C19*D19 -> 84 | F19: =C19-E19 -> 36
B20: =B6 -> KYC / Onboarding | C20: =E6 -> 200 | D20: =D6 -> 0.55 | E20: =C20*D20 -> 110 | F20: =C20-E20 -> 90
B21: =B7 -> Credit Decisioning | C21: =E7 -> 180 | D21: =D7 -> 0.45 | E21: =C21*D21 -> 81 | F21: =C21-E21 -> 99
B22: =B8 -> Complaints Handling | C22: =E8 -> 150 | D22: =D8 -> 0.4 | E22: =C22*D22 -> 60 | F22: =C22-E22 -> 90
B23: =B9 -> Fraud Investigation | C23: =E9 -> 80 | D23: =D9 -> 0.35 | E23: =C23*D23 -> 28 | F23: =C23-E23 -> 52
B24: =B10 -> Regulatory Reporting | C24: =E10 -> 60 | D24: =D10 -> 0.6 | E24: =C24*D24 -> 36 | F24: =C24-E24 -> 24
B25: =B11 -> Mortgage Processing | C25: =E11 -> 250 | D25: =D11 -> 0.5 | E25: =C25*D25 -> 125 | F25: =C25-E25 -> 125
B26: =B12 -> Customer Service (L1) | C26: =E12 -> 500 | D26: =D12 -> 0.75 | E26: =C26*D26 -> 375 | F26: =C26-E26 -> 125
B27: =B13 -> Internal Audit Prep | C27: =E13 -> 40 | D27: =D13 -> 0.3 | E27: =C27*D27 -> 12 | F27: =C27-E27 -> 28
B28: =B14 -> Procurement / Vendor Mgmt | C28: =E14 -> 30 | D28: =D14 -> 0.45 | E28: =C28*D28 -> 13.5 | F28: =C28-E28 -> 16.5
B29: TOTAL | C29: =SUM(C19:C28) -> 1610 | E29: =SUM(E19:E28) -> 924.5 | F29: =SUM(F19:F28) -> 685.5

Sheet Token Spend Scenarios
A1: Token Consumption: Scenario Analysis
A3: Scenarios: Annual Token Spend per FTE (GBP)
B4: Scenario | C4: Spend/FTE (GBP) | D4: Total Spend (GBP m) | E4: % of Salary | F4: Productivity Uplift | G4: Net ROI
B5: Current state | C5: =Assumptions!C37 -> 800 | D5: =C5*Assumptions!C40/1000000 -> 48 | E5: =C5/Assumptions!C4 -> 0.014545455 | F5: 0.05 | G5: =IF(C5=0,0,(F5*Assumptions!C4-C5)/C5) -> 2.4375
B6: Conservative | C6: 3000 | D6: =C6*Assumptions!C40/1000000 -> 180 | E6: =C6/Assumptions!C4 -> 0.054545455 | F6: 0.1 | G6: =IF(C6=0,0,(F6*Assumptions!C4-C6)/C6) -> 0.83333333
B7: a16z baseline | C7: =Assumptions!C36 -> 6700 | D7: =C7*Assumptions!C40/1000000 -> 402 | E7: =C7/Assumptions!C4 -> 0.12181818 | F7: 0.2 | G7: =IF(C7=0,0,(F7*Assumptions!C4-C7)/C7) -> 0.64179104
B8: Moderate | C8: 15000 | D8: =C8*Assumptions!C40/1000000 -> 900 | E8: =C8/Assumptions!C4 -> 0.27272727 | F8: 0.35 | G8: =IF(C8=0,0,(F8*Assumptions!C4-C8)/C8) -> 0.28333333
B9: Huang benchmark | C9: =Assumptions!C35 -> 27500 | D9: =C9*Assumptions!C40/1000000 -> 1650 | E9: =C9/Assumptions!C4 -> 0.5 | F9: 0.5 | G9: =IF(C9=0,0,(F9*Assumptions!C4-C9)/C9) -> 0
B10: Aggressive | C10: 40000 | D10: =C10*Assumptions!C40/1000000 -> 2400 | E10: =C10/Assumptions!C4 -> 0.72727273 | F10: 0.65 | G10: =IF(C10=0,0,(F10*Assumptions!C4-C10)/C10) -> -0.10625
A12: Jevons Paradox: Price Decline vs Consumption Growth
B13: Year | C13: Token Price Index | D13: Consumption Index | E13: Total Spend Index | F13: Spend (GBP m)
B14: 2026 | C14: 1 | D14: 1 | E14: =C14*D14 -> 1 | F14: =E14*Assumptions!C43 -> 48
B15: 2027 | C15: =C14*(1-Assumptions!C21) -> 0.6 | D15: =D14*(1+Assumptions!C21*2) -> 1.8 | E15: =C15*D15 -> 1.08 | F15: =E15*Assumptions!C43 -> 51.84
B16: 2028 | C16: =C15*(1-Assumptions!C21) -> 0.36 | D16: =D15*(1+Assumptions!C21*2) -> 3.24 | E16: =C16*D16 -> 1.1664 | F16: =E16*Assumptions!C43 -> 55.9872
B17: 2029 | C17: =C16*(1-Assumptions!C21) -> 0.216 | D17: =D16*(1+Assumptions!C21*2) -> 5.832 | E17: =C17*D17 -> 1.259712 | F17: =E17*Assumptions!C43 -> 60.466176
B18: 2030 | C18: =C17*(1-Assumptions!C21) -> 0.1296 | D18: =D17*(1+Assumptions!C21*2) -> 10.4976 | E18: =C18*D18 -> 1.360489 | F18: =E18*Assumptions!C43 -> 65.30347
B19: 2031 | C19: =C18*(1-Assumptions!C21) -> 0.07776 | D19: =D18*(1+Assumptions!C21*2) -> 18.89568 | E19: =C19*D19 -> 1.4693281 | F19: =E19*Assumptions!C43 -> 70.527748
B21: Note: Jevons multiplier (consumption growth = 2x price decline) is editable in Year 1+ cells

Sheet Intangibles Risk
A1: Legacy Intangibles: Impairment Scenario Analysis
A3: Capitalised Software by Category (editable)
B4: Software Category | C4: Carrying Value (GBP m) | D4: AI Vulnerability % | E4: Exposure (GBP m) | F4: Remaining Useful Life (yrs) | G4: Annual Amortisation (GBP m)
B5: Core banking platform | C5: 1200 | D5: 0.15 | E5: =C5*D5 -> 180 | F5: 8 | G5: =C5/F5 -> 150
B6: Risk & compliance engines | C6: 600 | D6: 0.3 | E6: =C6*D6 -> 180 | F6: 6 | G6: =C6/F6 -> 100
B7: Payments infrastructure | C7: 500 | D7: 0.2 | E7: =C7*D7 -> 100 | F7: 7 | G7: =C7/F7 -> 71.428571
B8: Customer channels (web/mobile) | C8: 400 | D8: 0.4 | E8: =C8*D8 -> 160 | F8: 4 | G8: =C8/F8 -> 100
B9: Data & analytics platforms | C9: 350 | D9: 0.5 | E9: =C9*D9 -> 175 | F9: 5 | G9: =C9/F9 -> 70
B10: Internal tooling & workflow | C10: 250 | D10: 0.6 | E10: =C10*D10 -> 150 | F10: 4 | G10: =C10/F10 -> 62.5
B11: Legacy mainframe systems | C11: 200 | D11: 0.1 | E11: =C11*D11 -> 20 | F11: 10 | G11: =C11/F11 -> 20
B12: TOTAL | C12: =SUM(C5:C11) -> 3500 | E12: =SUM(E5:E11) -> 965 | G12: =SUM(G5:G11) -> 573.92857
A14: Impairment Timing Scenarios
B15: Scenario | C15: Trigger Year | D15: Impairment % of Exposure | E15: Write-down (GBP m) | F15: Impact on CET1 (bps) | G15: Impact on Cost:Income
B16: Assumed CET1 ratio (%) | C16: 0.135 | G16: Current CET1 ratio
B17: Assumed Risk-Weighted Assets (GBP bn) | C17: 180
B18: Assumed total operating costs (GBP bn) | C18: 8.5
B19: Assumed total income (GBP bn) | C19: 14
B21: Scenario | C21: Trigger Year | D21: Impairment % of Exposure | E21: Write-down (GBP m) | F21: Impact on CET1 (bps) | G21: Impact on Cost:Income
B22: Gradual (5-year transition) | C22: 2028 | D22: 0.4 | E22: =E12*D22 -> 386 | F22: =(E22/1000)/(C17)*10000 -> 21.444444 | G22: =(C18+(E22/1000))/C19 -> 0.63471429
B23: Accelerated (AI capability jump) | C23: 2027 | D23: 0.65 | E23: =E12*D23 -> 627.25 | F23: =(E23/1000)/(C17)*10000 -> 34.847222 | G23: =(C18+(E23/1000))/C19 -> 0.65194643
B24: Sudden (regulatory mandate) | C24: 2026 | D24: 0.8 | E24: =E12*D24 -> 772 | F24: =(E24/1000)/(C17)*10000 -> 42.888889 | G24: =(C18+(E24/1000))/C19 -> 0.66228571

Sheet Investor View
A1: Investor Lens: AI Transition Impact on Key Metrics
A3: Scenario: Cost:Income Ratio Trajectory
B4: Year | C4: AI Cost Savings (GBP m) | D4: AI Investment (GBP m) | E4: Net Impact (GBP m) | F4: Adj. Cost:Income | G4: Peer Average C:I
B5: 2026 | C5: ='Process Comparison'!I15*0.2/1000000 -> 2.4730677 | D5: 150 | E5: =C5-D5 -> -147.52693 | F5: =('Intangibles Risk'!C18*1000-E5)/('Intangibles Risk'!C19*1000) -> 0.6176805 | G5: 0.58
B6: 2027 | C6: ='Process Comparison'!I15*0.4/1000000 -> 4.9461354 | D6: 200 | E6: =C6-D6 -> -195.05386 | F6: =('Intangibles Risk'!C18*1000-E6)/('Intangibles Risk'!C19*1000) -> 0.62107528 | G6: 0.565
B7: 2028 | C7: ='Process Comparison'!I15*0.6/1000000 -> 7.4192031 | D7: 180 | E7: =C7-D7 -> -172.5808 | F7: =('Intangibles Risk'!C18*1000-E7)/('Intangibles Risk'!C19*1000) -> 0.61947006 | G7: 0.55
B8: 2029 | C8: ='Process Comparison'!I15*0.8/1000000 -> 9.8922709 | D8: 150 | E8: =C8-D8 -> -140.10773 | F8: =('Intangibles Risk'!C18*1000-E8)/('Intangibles Risk'!C19*1000) -> 0.61715055 | G8: 0.535
B9: 2030 | C9: ='Process Comparison'!I15*1/1000000 -> 12.365339 | D9: 120 | E9: =C9-D9 -> -107.63466 | F9: =('Intangibles Risk'!C18*1000-E9)/('Intangibles Risk'!C19*1000) -> 0.61483105 | G9: 0.52
A12: AI Disclosure Readiness Checklist
B13: Disclosure Area | C13: Current Status | D13: Required By | E13: Owner | F13: Risk if Absent
B14: AI investment quantum | C14: Partial | D14: FY 2026 | E14: CFO | F14: Peer comparison gap
B15: Token consumption metrics | C15: Not tracked | D15: H1 2027 | E15: CIO | F15: Productivity narrative gap
B16: Intangibles obsolescence risk | C16: Not disclosed | D16: FY 2026 | E16: CFO / Audit | F16: Sudden write-down risk
B17: Workforce transition plan | C17: In development | D17: FY 2026 | E17: CHRO | F17: ESG / social licence risk
B18: AI error rate / quality metrics | C18: Not reported | D18: H1 2027 | E18: CRO | F18: Operational risk narrative
B19: Accounting policy (capex/opex) | C19: Under review | D19: FY 2026 | E19: CFO / External Audit | F19: Peer divergence

Sheet Sensitivity
A1: Sensitivity Analysis: What Breaks the Model?
A3: Break-even Analysis
B4: Human cost per task (GBP) | C4: =Assumptions!C31 -> 26.964286
B5: AI cost per task (GBP) | C5: =Assumptions!C30 -> 25.861714
B6: Cost ratio (AI / Human) | C6: =C5/C4 -> 0.95910993
B7: Current saving per task (GBP) | C7: =C4-C5 -> 1.1025714
A9: What AI error rate breaks even with human cost?
B10: Break-even AI error rate | C10: =(Assumptions!C31-Assumptions!C19-Assumptions!C29)/Assumptions!C26 -> 0.052205143 | D10: Error rate at which AI cost = human cost
B11: Current AI error rate | C11: =Assumptions!C25 -> 0.05
B12: Headroom (break-even less current) | C12: =C10-C11 -> 0.0022051429 | D12: Positive = safe margin
A14: What token price makes AI more expensive than humans?
B15: Crossover input token price (per 1M, GBP) | C15: =(Assumptions!C31-Assumptions!C29-(Assumptions!C25*Assumptions!C26)-(Assumptions!C16/1000000*Assumptions!C14)*(1+Assumptions!C18))/(Assumptions!C15/1000000*(1+Assumptions!C18)) -> 410.85979 | D15: Input token price at which AI becomes more expensive
B16: Current input token price (per 1M, GBP) | C16: =Assumptions!C13 -> 2.5
B17: Multiple of current price to break even | C17: =C15/C16 -> 164.34392 | D17: Higher = more resilient
A19: Oversight Sensitivity
B20: If oversight requirement doubles: | C20: =Assumptions!C19+(Assumptions!C27*(Assumptions!C28/60)*Assumptions!C8) -> 0.86171429 | D20: Total AI cost per task with 2x oversight
B21: If oversight requirement triples: | C21: =Assumptions!C19+2*(Assumptions!C27*(Assumptions!C28/60)*Assumptions!C8) -> 1.7099286 | D21: Total AI cost per task with 3x oversight
B22: Oversight % that breaks even with human | C22: =(Assumptions!C31-Assumptions!C19-(Assumptions!C25*Assumptions!C26))/(Assumptions!C28/60*Assumptions!C8) -> 0.34498105 | D22: Maximum oversight before AI becomes more expensive
